<?xml version="1.0"?>
<robot xmlns:xacro="http://www.ros.org/wiki/xacro" name="lab3_robot">

  <material name="green">
    <color rgba="0 0.5 0 1"/>
  </material>
  <material name="black">
    <color rgba="0 0 0 1"/>
  </material>

  <xacro:macro name="default_inertia">
    <inertial>
      <mass value="10"/>
      <inertia ixx="1e-3" ixy="0.0" ixz="0.0" iyy="1e-3" iyz="0.0" izz="1e-3"/>
    </inertial>
  </xacro:macro>

  <xacro:property name="base_width" value="0.4" />
  <xacro:property name="base_height" value="0.2" />
  <xacro:property name="base_dept" value="0.1" />
  <link name="base_link">
    <visual>
      <geometry>
        <box size="${base_width} ${base_height} ${base_dept}"/>
      </geometry>
      <material name="black"/>
    </visual>
    <collision>
      <geometry>
        <box size="${base_width} ${base_height} ${base_dept}"/>
      </geometry>
    </collision>
    <xacro:default_inertia />
  </link>

  <xacro:property name="wheel_length" value="0.05" />
  <xacro:property name="wheel_radius" value="0.1" />
  <xacro:macro name="wheel" params="name">
  <link name="${name}">
    <visual>
      <geometry>
        <cylinder length="${wheel_length}" radius="${wheel_radius}"/>
      </geometry>
      <origin rpy="0 1.57075 1.57075"/>
      <material name="green"/>
    </visual>
    <collision>
      <geometry>
        <cylinder length="${wheel_length}" radius="${wheel_radius}"/>
      </geometry>
    </collision>
    <xacro:default_inertia />
  </link>
  </xacro:macro>

  <xacro:wheel name="left_wheel" />
  <xacro:wheel name="right_wheel" />
  <xacro:wheel name="left_wheel_2" />
  <xacro:wheel name="right_wheel_2" />

  <joint name="base_to_left_wheel" type="continuous">
    <parent link="base_link"/>
    <child link="left_wheel"/>
    <axis xyz="0 1 0"/>
    <origin xyz="-${base_width/2} -${base_height/2} 0"/>
  </joint>
  <joint name="base_to_right_wheel" type="continuous">
    <parent link="base_link"/>
    <child link="right_wheel"/>
    <axis xyz="0 1 0"/>
    <origin xyz="${base_width/2} ${base_height/2} 0"/>
  </joint>
  <joint name="base_to_right_wheel_2" type="continuous">
    <parent link="base_link"/>
    <child link="right_wheel_2"/>
    <axis xyz="0 1 0"/>
    <origin xyz="-${base_width/2} ${base_height/2} 0"/>
  </joint>
  <joint name="base_to_left_wheel_2" type="continuous">
    <parent link="base_link"/>
    <child link="left_wheel_2"/>
    <axis xyz="0 1 0"/>
    <origin xyz="${base_width/2} -${base_height/2} 0"/>
  </joint>
  
</robot>
